[2024-05-08T12:03:09.807+0000] {task_context_logger.py:104} ERROR - Executor reports task instance <TaskInstance: dag_result.send_mail_task scheduled__2024-05-07T00:00:00+00:00 [queued]> finished (success) although the task says it's queued. (Info: None) Was the task killed externally?
